Failure in python_out_vs_err.py:

  The CHECK on line 17 wants:
    things should be cool

  which failed to match line stdout:2:
    now stdout is broken

  Context:
    fine so far
    now stdout is broken <= does not match CHECK on line 17: things should be cool

  There were no remaining checks left to match stderr:1:
    something failed

  Context:
    something failed <= no more checks

  when running command:
    /usr/bin/python3 python_out_vs_err.py
